Workbook

Sheet Main_260329
A1: Class+Node [(Identifier (Key)] | B1: Class [Not chosen] | C1: Node [Not chosen] | D1: Required Mods [Not chosen] | E1: English [Source string] | F1: Korean (한국어) [Translation]
A2: AbilityDef+AM_AnalyzeCreature.label | B2: AbilityDef | C2: AM_AnalyzeCreature.label | E2: analyze creature | F2: 생물 분석
A3: AbilityDef+AM_AnalyzeCreature.description | B3: AbilityDef | C3: AM_AnalyzeCreature.description | E3: This ability allows the colonist to scan animals in the map and add them to a genetic database, receiving bonuses depending on the number of animals scanned.\n\nIt is very low range and some animals will move out of range constantly, so they can be downed first to make it easier.\n\nNote however that it won't work on dead animals, and it will also fail if no database has been built yet. | F3: 생물을 분석해 생물전서에 등록합니다. 분석한 생물의 종류에 따라 추가 효과를 받습니다.\n\n범위가 매우 좁고 분석 중인 생물이 범위 바깥으로 이동할 수도 있으므로, 생물을 먼저 쓰러트린 후 능력을 사용하는 것을 추천합니다.\n\n참고: 죽은 생물에게는 능력이 작동하지 않습니다. 아직 생물전서를 만들지 않은 경우에도 마찬가지입니다.
A4: AbilityDef+AM_ConvertStone.label | B4: AbilityDef | C4: AM_ConvertStone.label | E4: convert to pristine limestone | F4: 완벽한 석회암으로 변환
A5: AbilityDef+AM_ConvertStone.description | B5: AbilityDef | C5: AM_ConvertStone.description | E5: This ability allows the master architect to convert any stone block (for mod compatibility defined as anything with "Blocks" in its defName) to Pristine limestone, a stone that is both beautiful and damage resistant.\n\nTo do this, the architect uses... err... mechanites... or something... Look, I just wanted a new rock type to build pretty pyramids with, ok? | F5: 석재를 아름답고 손상에 강한 완벽한 석회암으로 변환합니다.
A6: AbilityDef+AM_FinishConstruction.label | B6: AbilityDef | C6: AM_FinishConstruction.label | E6: finish construction | F6: 완공
A7: AbilityDef+AM_FinishConstruction.description | B7: AbilityDef | C7: AM_FinishConstruction.description | E7: Once every 10 days the master architect can use this ability to finish the construction of a blueprint. | F7: 자원 운반이 완료된 청사진의 건설을 즉시 완료합니다.
A8: AbilityDef+AM_OcularConversion.label | B8: AbilityDef | C8: AM_OcularConversion.label | E8: ocular conversion | F8: 눈알 변환
A9: AbilityDef+AM_OcularConversion.description | B9: AbilityDef | C9: AM_OcularConversion.description | E9: Converts trees. | F9: 나무를 변환합니다.
A10: AbilityDef+AM_ChangeStyle.label | B10: AbilityDef | C10: AM_ChangeStyle.label | E10: change style | F10: 양식 변경
A11: AbilityDef+AM_ChangeStyle.description | B11: AbilityDef | C11: AM_ChangeStyle.description | E11: Change the styling of an item or building. Bear in mind that only the styles present in the colony's primary ideo can be used to swap (this can be changed in mod options to allow ALL possible styles). | F11: 물건이나 건물의 양식을 변경합니다.
A12: AbilityDef+AM_ChangeStyleRandom.label | B12: AbilityDef | C12: AM_ChangeStyleRandom.label | E12: change style, random | F12: 양식 변경 - 무작위
A13: AbilityDef+AM_ChangeStyleRandom.description | B13: AbilityDef | C13: AM_ChangeStyleRandom.description | E13: Change the styling of an item or building to a random supported style. Bear in mind that only the styles present in the colony's primary ideo can be used to swap (this can be changed in mod options to allow ALL possible styles). | F13: 물건이나 건물의 양식을 무작위로 변경합니다.
... A2567: ThoughtDef+AM_CorpseRumThought.stages.0.description | B2567: ThoughtDef | C2567: AM_CorpseRumThought.stages.0.description | E2567: The rum was so delicious, it allows me to reminisce fondly about our fallen comrades. | F2567: 럼주가 너무 맛있어서 쓰러진 전우들을 추억할 수 있어.
A2568: AbilityDef+AM_PsychicDeathKnell.label | B2568: AbilityDef | C2568: AM_PsychicDeathKnell.label | D2568: Royalty | E2568: psychic death knell | F2568: 죽음의 종소리
A2569: AbilityDef+AM_PsychicDeathKnell.description | B2569: AbilityDef | C2569: AM_PsychicDeathKnell.description | D2569: Royalty | E2569: Forcefully extract the latent psychic energy from a downed foe. Animals don't have enough intelligence to be of any use in this regard.\n\nIf the person casting the ability doesn't have psychic powers, they'll just receive a minor healing effect and a mood boost. If the person does have at least level 1 psychic powers this ability will recharge his or her focus, but will generate 30% of maximum psychic heat. | F2569: 쓰러져있는 적의 잠재된 정신 에너지를 강제로 뽑아냅니다. 동물은 이 능력의 대상이 될 정도의 지능을 가지고 있지 않습니다.\n\n이 능력을 시전하는 시전자가 초능력을 가지고 있지 않다면 약간의 회복 효과와 기분 보너스만 받습니다. 시전자가 1단계의 초능력이라도 가지고 있으면 이 능력은 시전자의 초집중을 재충전하지만, 신경열을 30% 증가시킵니다.
A2570: JobDef+AM_AnimaBurialLink.reportString | B2570: JobDef | C2570: AM_AnimaBurialLink.reportString | D2570: Royalty | E2570: linking TargetA. | F2570: {TargetA}(와)과 정신 연결 중
A2571: MemeDef+AM_PsychicVampirism.label | B2571: MemeDef | C2571: AM_PsychicVampirism.label | D2571: Royalty | E2571: psychic vampirism | F2571: 정신력 흡혈귀
A2572: MemeDef+AM_PsychicVampirism.description | B2572: MemeDef | C2572: AM_PsychicVampirism.description | D2572: Royalty | E2572: Meditation is useless and a waste of time. If we want to master the powers of the mind we will have to rip the psychic energy from the still pulsating brains of our enemies. | F2572: 명상은 쓸모없고 시간낭비다. 우리가 정신의 힘을 지배하고 싶다면 적들의 고통치는 뇌에서 정신력을 뜯어내야 한다.
A2573: MemeDef+AM_PsychicVampirism.generalRules.rulesStrings.0 | B2573: MemeDef | C2573: AM_PsychicVampirism.generalRules.rulesStrings.0 | D2573: Royalty | E2573: memeAdjective->draining | F2573: memeAdjective->흡수하는
A2574: MemeDef+AM_PsychicVampirism.generalRules.rulesStrings.1 | B2574: MemeDef | C2574: AM_PsychicVampirism.generalRules.rulesStrings.1 | D2574: Royalty | E2574: memeAdjective->psychic | F2574: memeAdjective->정신력
A2575: MemeDef+AM_PsychicVampirism.generalRules.rulesStrings.2 | B2575: MemeDef | C2575: AM_PsychicVampirism.generalRules.rulesStrings.2 | D2575: Royalty | E2575: memeHyphenPrefix->mind | F2575: memeHyphenPrefix->정신
A2576: MemeDef+AM_PsychicVampirism.generalRules.rulesStrings.3 | B2576: MemeDef | C2576: AM_PsychicVampirism.generalRules.rulesStrings.3 | D2576: Royalty | E2576: memeConcept->psychic draining | F2576: memeConcept->정신력 흡수
A2577: MemeDef+AM_PsychicVampirism.generalRules.rulesStrings.4 | B2577: MemeDef | C2577: AM_PsychicVampirism.generalRules.rulesStrings.4 | D2577: Royalty | E2577: memeLeaderNoun->thaumaturge | F2577: memeLeaderNoun->기적술사
A2578: MemeDef+AM_PsychicVampirism.generalRules.rulesStrings.5 | B2578: MemeDef | C2578: AM_PsychicVampirism.generalRules.rulesStrings.5 | D2578: Royalty | E2578: memeMoralist->sorcerer | F2578: memeMoralist->마법사
A2579: MemeDef+AM_PsychicVampirism.generalRules.rulesStrings.6 | B2579: MemeDef | C2579: AM_PsychicVampirism.generalRules.rulesStrings.6 | D2579: Royalty | E2579: memeMoralist->warlock | F2579: memeMoralist->주술사
... A3491: ThoughtDef+AM_TeaCeremonyTranscendent.stages.0.description | B3491: ThoughtDef | C3491: AM_TeaCeremonyTranscendent.stages.0.description | D3491: Vanilla Brewing Expanded | E3491: This ceremony was a profound experience, an unforgettable communion with the sacred tea. | F3491: 이 의식은 신성한 차와의 잊을 수 없는 교감, 심오한 경험이었어.
A3492: Keyed+AM_ArtTableExtraSpeed | B3492: Keyed | C3492: AM_ArtTableExtraSpeed | E3492: Art production speed: increased precept | F3492: 예술 작업 속도: 증가 규율
A3493: Keyed+AM_ExtraBluntArmorFactor | B3493: Keyed | C3493: AM_ExtraBluntArmorFactor | E3493: Armour: blunt precept | F3493: 갑옷: 둔탁함 규율
A3494: Keyed+AM_ExtraSharpArmorFactor | B3494: Keyed | C3494: AM_ExtraSharpArmorFactor | E3494: Armour: sharp precept | F3494: 갑옷: 날카로움 규율
A3495: Keyed+AM_ExtraHeatArmorFactor | B3495: Keyed | C3495: AM_ExtraHeatArmorFactor | E3495: Armour: heat precept | F3495: 갑옷: 열기 규율
A3496: Keyed+AM_MeditationFocusStrengthFactor | B3496: Keyed | C3496: AM_MeditationFocusStrengthFactor | E3496: Psyfocus gain: dampened precept | F3496: 초집중 획득: 약화
A3497: Keyed+AM_DespisedAnimals | B3497: Keyed | C3497: AM_DespisedAnimals | E3497: Despised Animals | F3497: 멸시받는 동물들
A3498: Keyed+AM_AddDespisedAnimals | B3498: Keyed | C3498: AM_AddDespisedAnimals | E3498: Despised Animal | F3498: 멸시받는 동물
A3499: Keyed+AM_AbilityNeedsADownedPawn | B3499: Keyed | C3499: AM_AbilityNeedsADownedPawn | E3499: This ability must target a downed sapient humanoid | F3499: 이 능력은 쓰러져있는 지성 있는 인간을 대상으로 해야합니다.
A3500: Keyed+AM_AbilityNeedsAValidAnimal | B3500: Keyed | C3500: AM_AbilityNeedsAValidAnimal | E3500: This ability must target a living, non-dryad animal | F3500: 이 능력은 살아있고, 나무지기가 아닌 동물을 대상으로 해야합니다.
A3501: Keyed+AM_AbilityNeedsABlueprint | B3501: Keyed | C3501: AM_AbilityNeedsABlueprint | E3501: This ability needs to target a building frame that is under construction | F3501: 이 능력은 건설 중인 청사진을 대상으로 해야 합니다.
A3502: Keyed+AM_AbilityNeedsResourcesDelivered | B3502: Keyed | C3502: AM_AbilityNeedsResourcesDelivered | E3502: All resources must have been delivered to the building frame | F3502: 모든 자원이 청사진에 전달되어야 합니다.
A3503: Keyed+AM_NoDataBaseFound | B3503: Keyed | C3503: AM_NoDataBaseFound | E3503: You'll need to build an animal database before this ability can be used | F3503: 이 능력을 사용하려면 먼저 생물전서를 건설해야 합니다.
... A3616: Keyed+AM_AllowHighImpactMemesForFluidIdeos_Tooltip | B3616: Keyed | C3616: AM_AllowHighImpactMemesForFluidIdeos_Tooltip | E3616: By default, fluid ideos only let you choose one meme with impact 1 or 2, blocking impact 3 memes from being chosen. With this option toggle you can make it so impact 3 memes are available too. | F3616: 기본적으로 유동적 사상에서는 영향력이 낮거나 보통인 가르침 하나만 선택할 수 있으며, 영향력이 높은 가르침은 선택할 수 없습니다. 이 옵션 토글을 사용하면 영향력이 높은 가르침도 사용할 수 있도록 설정할 수 있습니다.
...

Sheet 250210
A1: Class+Node [(Identifier (Key)] | B1: Class [Not chosen] | C1: Node [Not chosen] | D1: Required Mods [Not chosen] | E1: English [Source string] | F1: Korean (한국어) [Translation]
A2: AbilityDef+AM_AnalyzeCreature.label | B2: AbilityDef | C2: AM_AnalyzeCreature.label | E2: analyze creature | F2: 생물 분석
A3: AbilityDef+AM_AnalyzeCreature.description | B3: AbilityDef | C3: AM_AnalyzeCreature.description | E3: This ability allows the colonist to scan animals in the map and add them to a genetic database, receiving bonuses depending on the number of animals scanned.\n\nIt is very low range and some animals will move out of range constantly, so they can be downed first to make it easier.\n\nNote however that it won't work on dead animals, and it will also fail if no database has been built yet. | F3: 생물을 분석해 생물전서에 등록합니다. 분석한 생물의 종류에 따라 추가 효과를 받습니다.\n\n범위가 매우 좁고 분석 중인 생물이 범위 바깥으로 이동할 수도 있으므로, 생물을 먼저 쓰러트린 후 능력을 사용하는 것을 추천합니다.\n\n참고: 죽은 생물에게는 능력이 작동하지 않습니다. 아직 생물전서를 만들지 않은 경우에도 마찬가지입니다.
A4: AbilityDef+AM_ConvertStone.label | B4: AbilityDef | C4: AM_ConvertStone.label | E4: convert to pristine limestone | F4: 완벽한 석회암으로 변환
A5: AbilityDef+AM_ConvertStone.description | B5: AbilityDef | C5: AM_ConvertStone.description | E5: This ability allows the master architect to convert any stone block (for mod compatibility defined as anything with "Blocks" in its defName) to Pristine limestone, a stone that is both beautiful and damage resistant.\n\nTo do this, the architect uses... err... mechanites... or something... Look, I just wanted a new rock type to build pretty pyramids with, ok? | F5: 석재를 아름답고 손상에 강한 완벽한 석회암으로 변환합니다.
A6: AbilityDef+AM_FinishConstruction.label | B6: AbilityDef | C6: AM_FinishConstruction.label | E6: finish construction | F6: 완공
A7: AbilityDef+AM_FinishConstruction.description | B7: AbilityDef | C7: AM_FinishConstruction.description | E7: Once every 10 days the master architect can use this ability to finish the construction of a blueprint. | F7: 자원 운반이 완료된 청사진의 건설을 즉시 완료합니다.
A8: AbilityDef+AM_OcularConversion.label | B8: AbilityDef | C8: AM_OcularConversion.label | E8: ocular conversion | F8: 눈알 변환
A9: AbilityDef+AM_OcularConversion.description | B9: AbilityDef | C9: AM_OcularConversion.description | E9: Converts trees. | F9: 나무를 변환합니다.
A10: AbilityDef+AM_ChangeStyle.label | B10: AbilityDef | C10: AM_ChangeStyle.label | E10: change style | F10: 양식 변경
A11: AbilityDef+AM_ChangeStyle.description | B11: AbilityDef | C11: AM_ChangeStyle.description | E11: Change the styling of an item or building. Bear in mind that only the styles present in the colony's primary ideo can be used to swap (this can be changed in mod options to allow ALL possible styles). | F11: 물건이나 건물의 양식을 변경합니다.
A12: AbilityDef+AM_ChangeStyleRandom.label | B12: AbilityDef | C12: AM_ChangeStyleRandom.label | E12: change style, random | F12: 양식 변경 - 무작위
A13: AbilityDef+AM_ChangeStyleRandom.description | B13: AbilityDef | C13: AM_ChangeStyleRandom.description | E13: Change the styling of an item or building to a random supported style. Bear in mind that only the styles present in the colony's primary ideo can be used to swap (this can be changed in mod options to allow ALL possible styles). | F13: 물건이나 건물의 양식을 무작위로 변경합니다.
... A2567: ThoughtDef+AM_CorpseRumThought.stages.0.description | B2567: ThoughtDef | C2567: AM_CorpseRumThought.stages.0.description | E2567: The rum was so delicious, it allows me to reminisce fondly about our fallen comrades. | F2567: 럼주가 너무 맛있어서 쓰러진 전우들을 추억할 수 있어.
A2568: AbilityDef+AM_PsychicDeathKnell.label | B2568: AbilityDef | C2568: AM_PsychicDeathKnell.label | D2568: Royalty | E2568: psychic death knell | F2568: 죽음의 종소리
A2569: AbilityDef+AM_PsychicDeathKnell.description | B2569: AbilityDef | C2569: AM_PsychicDeathKnell.description | D2569: Royalty | E2569: Forcefully extract the latent psychic energy from a downed foe. Animals don't have enough intelligence to be of any use in this regard.\n\nIf the person casting the ability doesn't have psychic powers, they'll just receive a minor healing effect and a mood boost. If the person does have at least level 1 psychic powers this ability will recharge his or her focus, but will generate 30% of maximum psychic heat. | F2569: 쓰러져있는 적의 잠재된 정신 에너지를 강제로 뽑아냅니다. 동물은 이 능력의 대상이 될 정도의 지능을 가지고 있지 않습니다.\n\n이 능력을 시전하는 시전자가 초능력을 가지고 있지 않다면 약간의 회복 효과와 기분 보너스만 받습니다. 시전자가 1단계의 초능력이라도 가지고 있으면 이 능력은 시전자의 초집중을 재충전하지만, 신경열을 30% 증가시킵니다.
A2570: JobDef+AM_AnimaBurialLink.reportString | B2570: JobDef | C2570: AM_AnimaBurialLink.reportString | D2570: Royalty | E2570: linking TargetA. | F2570: {TargetA}(와)과 정신 연결 중
A2571: MemeDef+AM_PsychicVampirism.label | B2571: MemeDef | C2571: AM_PsychicVampirism.label | D2571: Royalty | E2571: psychic vampirism | F2571: 정신력 흡혈귀
A2572: MemeDef+AM_PsychicVampirism.description | B2572: MemeDef | C2572: AM_PsychicVampirism.description | D2572: Royalty | E2572: Meditation is useless and a waste of time. If we want to master the powers of the mind we will have to rip the psychic energy from the still pulsating brains of our enemies. | F2572: 명상은 쓸모없고 시간낭비다. 우리가 정신의 힘을 지배하고 싶다면 적들의 고통치는 뇌에서 정신력을 뜯어내야 한다.
A2573: MemeDef+AM_PsychicVampirism.generalRules.rulesStrings.0 | B2573: MemeDef | C2573: AM_PsychicVampirism.generalRules.rulesStrings.0 | D2573: Royalty | E2573: memeAdjective->draining | F2573: memeAdjective->흡수하는
A2574: MemeDef+AM_PsychicVampirism.generalRules.rulesStrings.1 | B2574: MemeDef | C2574: AM_PsychicVampirism.generalRules.rulesStrings.1 | D2574: Royalty | E2574: memeAdjective->psychic | F2574: memeAdjective->정신력
A2575: MemeDef+AM_PsychicVampirism.generalRules.rulesStrings.2 | B2575: MemeDef | C2575: AM_PsychicVampirism.generalRules.rulesStrings.2 | D2575: Royalty | E2575: memeHyphenPrefix->mind | F2575: memeHyphenPrefix->정신
A2576: MemeDef+AM_PsychicVampirism.generalRules.rulesStrings.3 | B2576: MemeDef | C2576: AM_PsychicVampirism.generalRules.rulesStrings.3 | D2576: Royalty | E2576: memeConcept->psychic draining | F2576: memeConcept->정신력 흡수
A2577: MemeDef+AM_PsychicVampirism.generalRules.rulesStrings.4 | B2577: MemeDef | C2577: AM_PsychicVampirism.generalRules.rulesStrings.4 | D2577: Royalty | E2577: memeLeaderNoun->thaumaturge | F2577: memeLeaderNoun->기적술사
A2578: MemeDef+AM_PsychicVampirism.generalRules.rulesStrings.5 | B2578: MemeDef | C2578: AM_PsychicVampirism.generalRules.rulesStrings.5 | D2578: Royalty | E2578: memeMoralist->sorcerer | F2578: memeMoralist->마법사
A2579: MemeDef+AM_PsychicVampirism.generalRules.rulesStrings.6 | B2579: MemeDef | C2579: AM_PsychicVampirism.generalRules.rulesStrings.6 | D2579: Royalty | E2579: memeMoralist->warlock | F2579: memeMoralist->주술사
... A3491: ThoughtDef+AM_TeaCeremonyTranscendent.stages.0.description | B3491: ThoughtDef | C3491: AM_TeaCeremonyTranscendent.stages.0.description | D3491: Vanilla Brewing Expanded | E3491: This ceremony was a profound experience, an unforgettable communion with the sacred tea. | F3491: 이 의식은 신성한 차와의 잊을 수 없는 교감, 심오한 경험이었어.
A3492: Keyed+AM_ArtTableExtraSpeed | B3492: Keyed | C3492: AM_ArtTableExtraSpeed | E3492: Art production speed: increased precept | F3492: 예술 작업 속도: 증가 규율
A3493: Keyed+AM_ExtraBluntArmorFactor | B3493: Keyed | C3493: AM_ExtraBluntArmorFactor | E3493: Armour: blunt precept | F3493: 갑옷: 둔탁함 규율
A3494: Keyed+AM_ExtraSharpArmorFactor | B3494: Keyed | C3494: AM_ExtraSharpArmorFactor | E3494: Armour: sharp precept | F3494: 갑옷: 날카로움 규율
A3495: Keyed+AM_ExtraHeatArmorFactor | B3495: Keyed | C3495: AM_ExtraHeatArmorFactor | E3495: Armour: heat precept | F3495: 갑옷: 열기 규율
A3496: Keyed+AM_MeditationFocusStrengthFactor | B3496: Keyed | C3496: AM_MeditationFocusStrengthFactor | E3496: Psyfocus gain: dampened precept | F3496: 초집중 획득: 약화
A3497: Keyed+AM_DespisedAnimals | B3497: Keyed | C3497: AM_DespisedAnimals | E3497: Despised Animals | F3497: 멸시받는 동물들
A3498: Keyed+AM_AddDespisedAnimals | B3498: Keyed | C3498: AM_AddDespisedAnimals | E3498: Despised Animal | F3498: 멸시받는 동물
A3499: Keyed+AM_AbilityNeedsADownedPawn | B3499: Keyed | C3499: AM_AbilityNeedsADownedPawn | E3499: This ability must target a downed sapient humanoid | F3499: 이 능력은 쓰러져있는 지성 있는 인간을 대상으로 해야합니다.
A3500: Keyed+AM_AbilityNeedsAValidAnimal | B3500: Keyed | C3500: AM_AbilityNeedsAValidAnimal | E3500: This ability must target a living, non-dryad animal | F3500: 이 능력은 살아있고, 나무지기가 아닌 동물을 대상으로 해야합니다.
A3501: Keyed+AM_AbilityNeedsABlueprint | B3501: Keyed | C3501: AM_AbilityNeedsABlueprint | E3501: This ability needs to target a building frame that is under construction | F3501: 이 능력은 건설 중인 청사진을 대상으로 해야 합니다.
A3502: Keyed+AM_AbilityNeedsResourcesDelivered | B3502: Keyed | C3502: AM_AbilityNeedsResourcesDelivered | E3502: All resources must have been delivered to the building frame | F3502: 모든 자원이 청사진에 전달되어야 합니다.
A3503: Keyed+AM_NoDataBaseFound | B3503: Keyed | C3503: AM_NoDataBaseFound | E3503: You'll need to build an animal database before this ability can be used | F3503: 이 능력을 사용하려면 먼저 생물전서를 건설해야 합니다.
... A3616: Keyed+AM_AllowHighImpactMemesForFluidIdeos_Tooltip | B3616: Keyed | C3616: AM_AllowHighImpactMemesForFluidIdeos_Tooltip | E3616: By default, fluid ideos only let you choose one meme with impact 1 or 2, blocking impact 3 memes from being chosen. With this option toggle you can make it so impact 3 memes are available too. | F3616: 기본적으로 유동적 사상에서는 영향력이 낮거나 보통인 가르침 하나만 선택할 수 있으며, 영향력이 높은 가르침은 선택할 수 없습니다. 이 옵션 토글을 사용하면 영향력이 높은 가르침도 사용할 수 있도록 설정할 수 있습니다.
...

Sheet 240721
A1: Class+Node [(Identifier (Key)] | B1: Class [Not chosen] | C1: Node [Not chosen] | D1: Required Mods [Not chosen] | E1: English [Source string] | F1: Korean (한국어) [Translation]
A2: AbilityDef+AM_AnalyzeCreature.label | B2: AbilityDef | C2: AM_AnalyzeCreature.label | E2: analyze creature | F2: 생물 분석
A3: AbilityDef+AM_AnalyzeCreature.description | B3: AbilityDef | C3: AM_AnalyzeCreature.description | E3: This ability allows the colonist to scan animals in the map and add them to a genetic database, receiving bonuses depending on the number of animals scanned.\n\nIt is very low range and some animals will move out of range constantly, so they can be downed first to make it easier.\n\nNote however that it won't work on dead animals, and it will also fail if no database has been built yet. | F3: 이 능력은 정착민이 지도에서 생물을 분석해 생물 데이터베이스에 추가하여 분석한 생물의 수에 따라 보너스를 받을 수 있게 합니다.\n\n이 능력은 범위가 매우 작고 어떤 생물들은 지속적으로 범위 밖으로 이동하기 때문에 생물을 먼저 쓰러트리고 능력을 쉽게 사용할 수도 있습니다.\n\n참고: 죽은 생물에게는 능력이 작동하지 않으며 아직 데이터베이스를 만들지 않은 경우에도 마찬가지입니다.
A4: AbilityDef+AM_ConvertStone.label | B4: AbilityDef | C4: AM_ConvertStone.label | E4: convert to pristine limestone | F4: 완벽한 석회암으로 변환
A5: AbilityDef+AM_ConvertStone.description | B5: AbilityDef | C5: AM_ConvertStone.description | E5: This ability allows the master architect to convert any stone block (for mod compatibility defined as anything with "Blocks" in its defName) to Pristine limestone, a stone that is both beautiful and damage resistant.\n\nTo do this, the architect uses... err... mechanites... or something... Look, I just wanted a new rock type to build pretty pyramids with, ok? | F5: 이 능력은 건축 장인이 다른 석재(모드 호환성을 위해 defName 에 "Blocks"으로 정의된 것)를 아름답고 손상에 강한 완벽한 석회암 석재로 변환시킵니다.\n\n이걸 사용해서 건축가는... 어... 메카나이트... 뭐 그런거... 난 그냥 예쁜 피라미드를 지을 수 있는 새로운 암석 종류를 원했을 뿐이야. 알겠어?
A6: AbilityDef+AM_FinishConstruction.label | B6: AbilityDef | C6: AM_FinishConstruction.label | E6: finish construction | F6: 완공
A7: AbilityDef+AM_FinishConstruction.description | B7: AbilityDef | C7: AM_FinishConstruction.description | E7: Once every 10 days the master architect can use this ability to finish the construction of a blueprint. | F7: 10일마다 한번, 건축 장인이 이 능력을 사용하여 자원 운반이 완료된 청사진의 건설을 즉시 완료할 수 있습니다.
A8: AbilityDef+AM_OcularConversion.label | B8: AbilityDef | C8: AM_OcularConversion.label | E8: ocular conversion | F8: 눈알 변환
A9: AbilityDef+AM_OcularConversion.description | B9: AbilityDef | C9: AM_OcularConversion.description | E9: Converts trees. | F9: 나무를 변환합니다.
A10: AbilityDef+AM_ChangeStyle.label | B10: AbilityDef | C10: AM_ChangeStyle.label | E10: change style | F10: 양식 변경
A11: AbilityDef+AM_ChangeStyle.description | B11: AbilityDef | C11: AM_ChangeStyle.description | E11: Change the styling of an item or building. Bear in mind that only the styles present in the colony's primary ideo can be used to swap (this can be changed in mod options to allow ALL possible styles). | F11: 정착지의 지도자가 이 능력으로 물건이나 건물의 양식을 바꿀 수 있습니다. 정착지의 기본 사상에 들어있는 양식 범주로만 변경할 수 있습니다. (모드 설정에서 가능한 모든 양식을 허용하도록 변경할 수 있습니다.)
A12: AbilityDef+AM_ChangeStyleRandom.label | B12: AbilityDef | C12: AM_ChangeStyleRandom.label | E12: change style, random | F12: 양식 변경 - 무작위
A13: AbilityDef+AM_ChangeStyleRandom.description | B13: AbilityDef | C13: AM_ChangeStyleRandom.description | E13: Change the styling of an item or building to a random supported style. Bear in mind that only the styles present in the colony's primary ideo can be used to swap (this can be changed in mod options to allow ALL possible styles). | F13: 아이템 또는 건물의 양식을 무작위로 변경합니다. 정착지의 이념에 맞는 양식으로만 변경됩니다. (모드 옵션에서 모든 양식을 허용하도록 변경할 수 있습니다)
... A232: MemeDef+AM_BiologicalDefilers.descriptionMaker.rules.rulesStrings.21 | B232: MemeDef | C232: AM_BiologicalDefilers.descriptionMaker.rules.rulesStrings.21 | E232: alienistProphecy(tag=meme_BiologicalDefilers)->We must destroy these lifeforms, for humanity has gone way too far. All the galaxy is being remade in the image of our original planet, and that is obscene. | F232: alienistProphecy(tag=meme_BiologicalDefilers)->우리는 이 생명체들을 파괴해야 한다. 인류는 너무 멀리 갔다. 은하계 전체가 우리의 원래 행성의 이미지로 재창조되고 있으며, 이는 혐오스럽다.
A233: MemeDef+AM_GauranlenSupremacy.label | B233: MemeDef | C233: AM_GauranlenSupremacy.label | E233: gauranlen supremacy | G233: 요정나무 지상주의 | H233: Vanilla Ideology Expanded - Anima Theme의 로드 유무에 따라 분기되어 패치로 해야함.
A234: MemeDef+AM_GauranlenSupremacy.description | B234: MemeDef | C234: AM_GauranlenSupremacy.description | E234: The symbiotic relationship between humanity, gauranlen trees and their dryads is sacred. We will defend and nurture the trees, and in return they will help us protect our colony.\n\n<color=#E5E54C>Restrictions:</color>\n - This meme can only be chosen if the Tree Connection meme is chosen too (alternatively, the Biological Corruptors meme in Alpha Animals).\n\n<color=#E5E54C>Gameplay effect:</color>\n - Colony will start with three Unshackled dryads. | G234: 인류와 요정나무, 그리고 나무의 나무지기 사이의 공생 관계는 신성하다. 우리는 나무를 지키고 보살필 것이다. 그러면 그 대가로 우리의 정착지를 보호하는 데 도움을 줄 것이다.\n\n<color=#E5E54C>제한:</color>\n - 이 가르침은 수목주의 혹은 부패주의 가르침을 선택한 경우에만 선택할 수 있습니다.\n\n<color=#E5E54C>게임 플레이 효과:</color>\n - 정착지는 묶여있지 않은 나무지기 셋과 함께 시작합니다. | H234: Vanilla Ideology Expanded - Anima Theme의 로드 유무에 따라 분기되어 패치로 해야함.
A235: MemeDef+AM_GauranlenSupremacy.generalRules.rulesStrings.0 | B235: MemeDef | C235: AM_GauranlenSupremacy.generalRules.rulesStrings.0 | E235: memeCreed->dryad | F235: memeCreed->나무지기
A236: MemeDef+AM_GauranlenSupremacy.generalRules.rulesStrings.1 | B236: MemeDef | C236: AM_GauranlenSupremacy.generalRules.rulesStrings.1 | E236: memeCreed->gauranlen tree | F236: memeCreed->요정나무
A237: MemeDef+AM_GauranlenSupremacy.generalRules.rulesStrings.2 | B237: MemeDef | C237: AM_GauranlenSupremacy.generalRules.rulesStrings.2 | E237: memeConcept->gauranlen trees | F237: memeConcept->요정나무들
A238: MemeDef+AM_GauranlenSupremacy.generalRules.rulesStrings.3 | B238: MemeDef | C238: AM_GauranlenSupremacy.generalRules.rulesStrings.3 | E238: memeConcept->dryads | F238: memeConcept->나무지기들
A239: MemeDef+AM_GauranlenSupremacy.generalRules.rulesStrings.4 | B239: MemeDef | C239: AM_GauranlenSupremacy.generalRules.rulesStrings.4 | E239: memeAdjective->druidic | F239: memeAdjective->드루이드의
A240: MemeDef+AM_GauranlenSupremacy.generalRules.rulesStrings.5 | B240: MemeDef | C240: AM_GauranlenSupremacy.generalRules.rulesStrings.5 | E240: memeAdjective->barky | F240: memeAdjective->나무껍질의
A241: MemeDef+AM_GauranlenSupremacy.generalRules.rulesStrings.6 | B241: MemeDef | C241: AM_GauranlenSupremacy.generalRules.rulesStrings.6 | E241: memeHyphenPrefix->tree | F241: memeHyphenPrefix->나무
A242: MemeDef+AM_GauranlenSupremacy.generalRules.rulesStrings.7 | B242: MemeDef | C242: AM_GauranlenSupremacy.generalRules.rulesStrings.7 | E242: memeHyphenPrefix->arbor | F242: memeHyphenPrefix->수목
A243: MemeDef+AM_GauranlenSupremacy.generalRules.rulesStrings.8 | B243: MemeDef | C243: AM_GauranlenSupremacy.generalRules.rulesStrings.8 | E243: memeHyphenPrefix->dryad | F243: memeHyphenPrefix->나무지기
A244: MemeDef+AM_GauranlenSupremacy.generalRules.rulesStrings.9 | B244: MemeDef | C244: AM_GauranlenSupremacy.generalRules.rulesStrings.9 | E244: memeLeaderNoun->dryadkeeper | F244: memeLeaderNoun->나무지기 수호자
A245: MemeDef+AM_GauranlenSupremacy.generalRules.rulesStrings.10 | B245: MemeDef | C245: AM_GauranlenSupremacy.generalRules.rulesStrings.10 | E245: memeLeaderNoun->arborist | F245: memeLeaderNoun->수목 재배자
A246: MemeDef+AM_GauranlenSupremacy.generalRules.rulesStrings.11 | B246: MemeDef | C246: AM_GauranlenSupremacy.generalRules.rulesStrings.11 | E246: memeLeaderAdjective->green | F246: memeLeaderAdjective->녹색의
... A1413: TerrainDef+AM_Tile_Futuristic_Kemetic.description | B1413: TerrainDef | C1413: AM_Tile_Futuristic_Kemetic.description | E1413: Fine steel plates with a hexagonal pattern for that ultra-technological look. | F1413: 극도로 기술적인 외형을 위해 육각형 무늬를 새긴 고급 철판입니다.
A1414: TerrainDef+AM_TilePristineLimestone.description | B1414: TerrainDef | C1414: AM_TilePristineLimestone.description | E1414: Carefully-cut and fit stone tiles for a castle feeling. They are pretty to look at, but they take a long time to lay.
A1415: TerrainDef+AM_TilePristineLimestone.label | B1415: TerrainDef | C1415: AM_TilePristineLimestone.label | E1415: pristine limestone tile | F1415: 완벽한 석회암 바닥
A1416: TerrainDef+AM_FlagstonePristineLimestone.description | B1416: TerrainDef | C1416: AM_FlagstonePristineLimestone.description | E1416: Roughly-cut stone tiles. These are not beautiful, but they make good surfaces for roads and outdoor walkways. Deconstructing flagstone yields no resources.
A1417: TerrainDef+AM_FlagstonePristineLimestone.label | B1417: TerrainDef | C1417: AM_FlagstonePristineLimestone.label | E1417: pristine limestone flagstone | F1417: 완벽한 석회암 판석
A1418: DesignatorDropdownGroupDef+AM_Floor_SteampunkTiles.label | B1418: DesignatorDropdownGroupDef | C1418: AM_Floor_SteampunkTiles.label | E1418: steampunk stone tiles | F1418: 스팀펑크 바닥
A1419: TerrainDef+AM_SteampunkTileSandstone.description | B1419: TerrainDef | C1419: AM_SteampunkTileSandstone.description | E1419: Carefully-cut and fit stone tiles in a Steampunk style. They are pretty to look at, but they take a long time to lay. | F1419: 스팀펑크 양식 돌 바닥입니다. 조심스럽게 깎고 다듬어 예쁘지만 시간이 오래 걸립니다.
A1420: TerrainDef+AM_SteampunkTileSandstone.label | B1420: TerrainDef | C1420: AM_SteampunkTileSandstone.label | E1420: steampunk sandstone tile | F1420: 스팀펑크 사암 바닥
A1421: TerrainDef+AM_SteampunkTileGranite.description | B1421: TerrainDef | C1421: AM_SteampunkTileGranite.description | E1421: Carefully-cut and fit stone tiles in a Steampunk style. They are pretty to look at, but they take a long time to lay. | F1421: 스팀펑크 양식 돌 바닥입니다. 조심스럽게 깎고 다듬어 예쁘지만 시간이 오래 걸립니다.
A1422: TerrainDef+AM_SteampunkTileGranite.label | B1422: TerrainDef | C1422: AM_SteampunkTileGranite.label | E1422: steampunk granite tile | F1422: 스팀펑크 화강암 바닥
A1423: TerrainDef+AM_SteampunkTileLimestone.description | B1423: TerrainDef | C1423: AM_SteampunkTileLimestone.description | E1423: Carefully-cut and fit stone tiles in a Steampunk style. They are pretty to look at, but they take a long time to lay. | F1423: 스팀펑크 양식 돌 바닥입니다. 조심스럽게 깎고 다듬어 예쁘지만 시간이 오래 걸립니다.
A1424: TerrainDef+AM_SteampunkTileLimestone.label | B1424: TerrainDef | C1424: AM_SteampunkTileLimestone.label | E1424: steampunk limestone tile | F1424: 스팀펑크 석회암 바닥
...

Sheet Sheet1 (2)
A1: Class+Node [(Identifier (Key)] | B1: Class [Not chosen] | C1: Required Mods [Not chosen] | D1: English [Source string] | G1: Korean (한국어) [Translation]
A2: AbilityDef+AM_AnalyzeCreature.label | B2: AbilityDef | D2: analyze creature | F2: =IF(E2="",IF(C2="",A2,C2),E2) -> AbilityDef+AM_AnalyzeCreature.label | G2: 생물 분석 | H2: =IF(ISERROR(E2),"",MATCH(F2,'240721'!$A$2:$A$2763,0)) -> 1
A3: AbilityDef+AM_AnalyzeCreature.description | B3: AbilityDef | D3: This ability allows the colonist to scan animals in the map and add them to a genetic database, receiving bonuses depending on the number of animals scanned.\n\nIt is very low range and some animals will move out of range constantly, so they can be downed first to make it easier.\n\nNote however that it won't work on dead animals, and it will also fail if no database has been built yet. | F3: =IF(E3="",IF(C3="",A3,C3),E3) -> AbilityDef+AM_AnalyzeCreature.description | G3: 이 능력은 정착민이 지도에서 생물을 분석해 생물 데이터베이스에 추가하여 분석한 생물의 수에 따라 보너스를 받을 수 있게 합니다.\n\n이 능력은 범위가 매우 작고 어떤 생물들은 지속적으로 범위 밖으로 이동하기 때문에 생물을 먼저 쓰러트리고 능력을 쉽게 사용할 수도 있습니다.\n\n참고: 죽은 생물에게는 능력이 작동하지 않으며 아직 데이터베이스를 만들지 않은 경우에도 마찬가지입니다. | H3: =IF(ISERROR(E3),"",MATCH(F3,'240721'!$A$2:$A$2763,0)) -> 2
A4: AbilityDef+AM_ConvertStone.label | B4: AbilityDef | D4: convert to pristine limestone | F4: =IF(E4="",IF(C4="",A4,C4),E4) -> AbilityDef+AM_ConvertStone.label | G4: 완벽한 석회암으로 변환 | H4: =IF(ISERROR(E4),"",MATCH(F4,'240721'!$A$2:$A$2763,0)) -> 3
A5: AbilityDef+AM_ConvertStone.description | B5: AbilityDef | D5: This ability allows the master architect to convert any stone block (for mod compatibility defined as anything with "Blocks" in its defName) to Pristine limestone, a stone that is both beautiful and damage resistant.\n\nTo do this, the architect uses... err... mechanites... or something... Look, I just wanted a new rock type to build pretty pyramids with, ok? | F5: =IF(E5="",IF(C5="",A5,C5),E5) -> AbilityDef+AM_ConvertStone.description | G5: 이 능력은 건축 장인이 다른 석재(모드 호환성을 위해 defName 에 "Blocks"으로 정의된 것)를 아름답고 손상에 강한 완벽한 석회암 석재로 변환시킵니다.\n\n이걸 사용해서 건축가는... 어... 메카나이트... 뭐 그런거... 난 그냥 예쁜 피라미드를 지을 수 있는 새로운 암석 종류를 원했을 뿐이야. 알겠어? | H5: =IF(ISERROR(E5),"",MATCH(F5,'240721'!$A$2:$A$2763,0)) -> 4
A6: AbilityDef+AM_FinishConstruction.label | B6: AbilityDef | D6: finish construction | F6: =IF(E6="",IF(C6="",A6,C6),E6) -> AbilityDef+AM_FinishConstruction.label | G6: 완공 | H6: =IF(ISERROR(E6),"",MATCH(F6,'240721'!$A$2:$A$2763,0)) -> 5
A7: AbilityDef+AM_FinishConstruction.description | B7: AbilityDef | D7: Once every 10 days the master architect can use this ability to finish the construction of a blueprint. | F7: =IF(E7="",IF(C7="",A7,C7),E7) -> AbilityDef+AM_FinishConstruction.description | G7: 10일마다 한번, 건축 장인이 이 능력을 사용하여 자원 운반이 완료된 청사진의 건설을 즉시 완료할 수 있습니다. | H7: =IF(ISERROR(E7),"",MATCH(F7,'240721'!$A$2:$A$2763,0)) -> 6
A8: AbilityDef+AM_ChangeStyle.label | B8: AbilityDef | D8: change style | F8: =IF(E8="",IF(C8="",A8,C8),E8) -> AbilityDef+AM_ChangeStyle.label | G8: 양식 변경 | H8: =IF(ISERROR(E8),"",MATCH(F8,'240721'!$A$2:$A$2763,0)) -> 9
A9: AbilityDef+AM_ChangeStyle.description | B9: AbilityDef | D9: Change the styling of an item or building. Bear in mind that only the styles present in the colony's primary ideo can be used to swap (this can be changed in mod options to allow ALL possible styles). | F9: =IF(E9="",IF(C9="",A9,C9),E9) -> AbilityDef+AM_ChangeStyle.description | G9: 정착지의 지도자가 이 능력으로 물건이나 건물의 양식을 바꿀 수 있습니다. 정착지의 기본 사상에 들어있는 양식 범주로만 변경할 수 있습니다. (모드 설정에서 가능한 모든 양식을 허용하도록 변경할 수 있습니다.) | H9: =IF(ISERROR(E9),"",MATCH(F9,'240721'!$A$2:$A$2763,0)) -> 10
A10: AbilityDef+AM_PsychicDeathKnell.label | B10: AbilityDef | D10: psychic death knell | F10: =IF(E10="",IF(C10="",A10,C10),E10) -> AbilityDef+AM_PsychicDeathKnell.label | G10: 죽음의 종소리 | H10: =IF(ISERROR(E10),"",MATCH(F10,'240721'!$A$2:$A$2763,0)) -> 2151
A11: AbilityDef+AM_PsychicDeathKnell.description | B11: AbilityDef | D11: Forcefully extract the latent psychic energy from a downed foe. Animals don't have enough intelligence to be of any use in this regard.\n\nIf the person casting the ability doesn't have psychic powers, they'll just receive a minor healing effect and a mood boost. If the person does have at least level 1 psychic powers this ability will recharge his or her focus, but will generate 30% of maximum psychic heat. | F11: =IF(E11="",IF(C11="",A11,C11),E11) -> AbilityDef+AM_PsychicDeathKnell.description | G11: 쓰러져있는 적의 잠재된 정신 에너지를 강제로 뽑아냅니다. 동물은 이 능력의 대상이 될 정도의 지능을 가지고 있지 않습니다.\n\n이 능력을 시전하는 시전자가 초능력을 가지고 있지 않다면 약간의 회복 효과와 기분 보너스만 받습니다. 시전자가 1단계의 초능력이라도 가지고 있으면 이 능력은 시전자의 초집중을 재충전하지만, 신경열을 30% 증가시킵니다. | H11: =IF(ISERROR(E11),"",MATCH(F11,'240721'!$A$2:$A$2763,0)) -> 2152
A12: AbilityDef+AM_OcularConversion.label | B12: AbilityDef | D12: ocular conversion | F12: =IF(E12="",IF(C12="",A12,C12),E12) -> AbilityDef+AM_OcularConversion.label | G12: 눈알 변환 | H12: =IF(ISERROR(E12),"",MATCH(F12,'240721'!$A$2:$A$2763,0)) -> 7
A13: AbilityDef+AM_OcularConversion.description | B13: AbilityDef | D13: Converts trees. | F13: =IF(E13="",IF(C13="",A13,C13),E13) -> AbilityDef+AM_OcularConversion.description | G13: 나무를 변환합니다. | H13: =IF(ISERROR(E13),"",MATCH(F13,'240721'!$A$2:$A$2763,0)) -> 8
... A22: BodyDef+AM_EyeBody.label | B22: BodyDef | D22: eye | F22: =IF(E22="",IF(C22="",A22,C22),E22) -> BodyDef+AM_EyeBody.label | G22: 눈 | H22: =IF(ISERROR(E22),"",MATCH(F22,'240721'!$A$2:$A$2763,0)) -> 19
A23: BodyDef+AM_EyeBody.corePart.parts.0.customLabel | B23: BodyDef | D23: stomach pouch | E23: BodyDef+AM_EyeBody.corePart.parts.stomach_pouch.customLabel | F23: =IF(E23="",IF(C23="",A23,C23),E23) -> BodyDef+AM_EyeBody.corePart.parts.stomach_pouch.customLabel | G23: 위 주머니 | H23: =IF(ISERROR(E23),"",MATCH(F23,'240721'!$A$2:$A$2763,0)) -> 20
A24: BodyDef+AM_EyeBody.corePart.parts.1.customLabel | B24: BodyDef | D24: gastrovascular cavity | E24: BodyDef+AM_EyeBody.corePart.parts.gastrovascular_cavity.customLabel | F24: =IF(E24="",IF(C24="",A24,C24),E24) -> BodyDef+AM_EyeBody.corePart.parts.gastrovascular_cavity.customLabel | G24: 위혈관 | H24: =IF(ISERROR(E24),"",MATCH(F24,'240721'!$A$2:$A$2763,0)) -> 21
A25: BodyDef+AM_EyeBody.corePart.parts.3.customLabel | B25: BodyDef | D25: first tentacle | E25: BodyDef+AM_EyeBody.corePart.parts.first_tentacle.customLabel | F25: =IF(E25="",IF(C25="",A25,C25),E25) -> BodyDef+AM_EyeBody.corePart.parts.first_tentacle.customLabel | G25: 첫 번째 촉수 | H25: =IF(ISERROR(E25),"",MATCH(F25,'240721'!$A$2:$A$2763,0)) -> 22
A26: BodyDef+AM_EyeBody.corePart.parts.4.customLabel | B26: BodyDef | D26: second tentacle | E26: BodyDef+AM_EyeBody.corePart.parts.second_tentacle.customLabel | F26: =IF(E26="",IF(C26="",A26,C26),E26) -> BodyDef+AM_EyeBody.corePart.parts.second_tentacle.customLabel | G26: 두 번째 촉수 | H26: =IF(ISERROR(E26),"",MATCH(F26,'240721'!$A$2:$A$2763,0)) -> 23
A27: BodyDef+AM_EyeBody.corePart.parts.5.customLabel | B27: BodyDef | D27: third tentacle | E27: BodyDef+AM_EyeBody.corePart.parts.third_tentacle.customLabel | F27: =IF(E27="",IF(C27="",A27,C27),E27) -> BodyDef+AM_EyeBody.corePart.parts.third_tentacle.customLabel | G27: 세 번째 촉수 | H27: =IF(ISERROR(E27),"",MATCH(F27,'240721'!$A$2:$A$2763,0)) -> 24
A28: BodyDef+AM_EyeBody.corePart.parts.2.parts.0.customLabel | B28: BodyDef | D28: eye | E28: BodyDef+AM_EyeBody.corePart.parts.2.parts.eye.customLabel | F28: =IF(E28="",IF(C28="",A28,C28),E28) -> BodyDef+AM_EyeBody.corePart.parts.2.parts.eye.customLabel | G28: 눈 | H28: =IF(ISERROR(E28),"",MATCH(F28,'240721'!$A$2:$A$2763,0)) -> 25
A29: BodyPartDef+AM_JellyfishTentacle.label | B29: BodyPartDef | D29: tentacle | F29: =IF(E29="",IF(C29="",A29,C29),E29) -> BodyPartDef+AM_JellyfishTentacle.label | G29: 촉수 | H29: =IF(ISERROR(E29),"",MATCH(F29,'240721'!$A$2:$A$2763,0)) -> 36
A30: BodyPartDef+AM_EyeBody.label | B30: BodyPartDef | D30: eye | F30: =IF(E30="",IF(C30="",A30,C30),E30) -> BodyPartDef+AM_EyeBody.label | G30: 눈 | H30: =IF(ISERROR(E30),"",MATCH(F30,'240721'!$A$2:$A$2763,0)) -> 37
A31: BodyPartGroupDef+AA_Body.label | B31: BodyPartGroupDef | D31: body | F31: =IF(E31="",IF(C31="",A31,C31),E31) -> BodyPartGroupDef+AA_Body.label | G31: 몸 | H31: =IF(ISERROR(E31),"",MATCH(F31,'240721'!$A$2:$A$2763,0)) -> 26
A32: BodyPartGroupDef+AA_Mouth.label | B32: BodyPartGroupDef | D32: mouth | F32: =IF(E32="",IF(C32="",A32,C32),E32) -> BodyPartGroupDef+AA_Mouth.label | G32: 입 | H32: =IF(ISERROR(E32),"",MATCH(F32,'240721'!$A$2:$A$2763,0)) -> 27
A33: BodyPartGroupDef+AA_Sting.label | B33: BodyPartGroupDef | D33: stinger | F33: =IF(E33="",IF(C33="",A33,C33),E33) -> BodyPartGroupDef+AA_Sting.label | G33: 침 | H33: =IF(ISERROR(E33),"",MATCH(F33,'240721'!$A$2:$A$2763,0)) -> 28
A34: BodyPartGroupDef+AA_PincerAttackTool.label | B34: BodyPartGroupDef | D34: pincer | F34: =IF(E34="",IF(C34="",A34,C34),E34) -> BodyPartGroupDef+AA_PincerAttackTool.label | G34: 집게 | H34: =IF(ISERROR(E34),"",MATCH(F34,'240721'!$A$2:$A$2763,0)) -> 29
A35: BodyPartGroupDef+AA_BladeAttackTool.label | B35: BodyPartGroupDef | D35: blade | F35: =IF(E35="",IF(C35="",A35,C35),E35) -> BodyPartGroupDef+AA_BladeAttackTool.label | G35: 칼날 | H35: =IF(ISERROR(E35),"",MATCH(F35,'240721'!$A$2:$A$2763,0)) -> 30
A36: BodyPartGroupDef+AA_TentacleAttackTool.label | B36: BodyPartGroupDef | D36: tentacle | F36: =IF(E36="",IF(C36="",A36,C36),E36) -> BodyPartGroupDef+AA_TentacleAttackTool.label | G36: 촉수 | H36: =IF(ISERROR(E36),"",MATCH(F36,'240721'!$A$2:$A$2763,0)) -> 31
A37: BodyPartGroupDef+AA_EyestalkAttackTool.label | B37: BodyPartGroupDef | D37: eyestalk | F37: =IF(E37="",IF(C37="",A37,C37),E37) -> BodyPartGroupDef+AA_EyestalkAttackTool.label | G37: 눈자루 | H37: =IF(ISERROR(E37),"",MATCH(F37,'240721'!$A$2:$A$2763,0)) -> 32
A38: BodyPartGroupDef+LegAttackTool.label | B38: BodyPartGroupDef | D38: leg | F38: =IF(E38="",IF(C38="",A38,C38),E38) -> BodyPartGroupDef+LegAttackTool.label | G38: 다리 | H38: =IF(ISERROR(E38),"",MATCH(F38,'240721'!$A$2:$A$2763,0)) -> 33
A39: BodyPartGroupDef+TuskAttackTool.label | B39: BodyPartGroupDef | D39: tusk | F39: =IF(E39="",IF(C39="",A39,C39),E39) -> BodyPartGroupDef+TuskAttackTool.label | G39: 엄니 | H39: =IF(ISERROR(E39),"",MATCH(F39,'240721'!$A$2:$A$2763,0)) -> 34
A40: BodyPartGroupDef+AA_Tail.label | B40: BodyPartGroupDef | D40: tail | F40: =IF(E40="",IF(C40="",A40,C40),E40) -> BodyPartGroupDef+AA_Tail.label | G40: 꼬리 | H40: =IF(ISERROR(E40),"",MATCH(F40,'240721'!$A$2:$A$2763,0)) -> 35
... A79: HediffDef+AM_ToxicBuildup.label | B79: HediffDef | D79: toxic buildup | F79: =IF(E79="",IF(C79="",A79,C79),E79) -> HediffDef+AM_ToxicBuildup.label | G79: 중독 | H79: =IF(ISERROR(E79),"",MATCH(F79,'240721'!$A$2:$A$2763,0)) -> 67
A80: HediffDef+AM_ToxicBuildup.stages.0.label | B80: HediffDef | D80: initial | E80: =NA() -> #N/A | F80: =IF(E80="",IF(C80="",A80,C80),E80) -> #N/A | G80: 초기 | H80: =IF(ISERROR(E80),"",MATCH(F80,'240721'!$A$2:$A$2763,0))
A81: HediffDef+AM_ToxicBuildup.stages.1.label | B81: HediffDef | D81: initial | E81: HediffDef+AM_ToxicBuildup.stages.initial.label | F81: =IF(E81="",IF(C81="",A81,C81),E81) -> HediffDef+AM_ToxicBuildup.stages.initial.label | G81: 초기 | H81: =IF(ISERROR(E81),"",MATCH(F81,'240721'!$A$2:$A$2763,0)) -> 68
A82: HediffDef+AM_ToxicBuildup.stages.2.label | B82: HediffDef | D82: minor | E82: HediffDef+AM_ToxicBuildup.stages.minor.label | F82: =IF(E82="",IF(C82="",A82,C82),E82) -> HediffDef+AM_ToxicBuildup.stages.minor.label | G82: 가벼움 | H82: =IF(ISERROR(E82),"",MATCH(F82,'240721'!$A$2:$A$2763,0)) -> 69
A83: HediffDef+AM_ToxicBuildup.stages.3.label | B83: HediffDef | D83: moderate | E83: HediffDef+AM_ToxicBuildup.stages.moderate.label | F83: =IF(E83="",IF(C83="",A83,C83),E83) -> HediffDef+AM_ToxicBuildup.stages.moderate.label | G83: 진행됨 | H83: =IF(ISERROR(E83),"",MATCH(F83,'240721'!$A$2:$A$2763,0)) -> 70
A84: HediffDef+AM_ToxicBuildup.stages.4.label | B84: HediffDef | D84: serious | E84: HediffDef+AM_ToxicBuildup.stages.serious.label | F84: =IF(E84="",IF(C84="",A84,C84),E84) -> HediffDef+AM_ToxicBuildup.stages.serious.label | G84: 심각함 | H84: =IF(ISERROR(E84),"",MATCH(F84,'240721'!$A$2:$A$2763,0)) -> 71
A85: HediffDef+AM_ToxicBuildup.stages.5.label | B85: HediffDef | D85: extreme | E85: HediffDef+AM_ToxicBuildup.stages.extreme.label | F85: =IF(E85="",IF(C85="",A85,C85),E85) -> HediffDef+AM_ToxicBuildup.stages.extreme.label | G85: 극심함 | H85: =IF(ISERROR(E85),"",MATCH(F85,'240721'!$A$2:$A$2763,0)) -> 72
A86: HediffDef+AM_Kamikaze.label | B86: HediffDef | D86: sudden detonation | F86: =IF(E86="",IF(C86="",A86,C86),E86) -> HediffDef+AM_Kamikaze.label | G86: 갑작스러운 폭발 | H86: =IF(ISERROR(E86),"",MATCH(F86,'240721'!$A$2:$A$2763,0)) -> 73
...
